Traceback (most recent call last):
  File "train_single_dqn.py", line 331, in <module>
    test(env, 100, "checkpoints/ckpt_3580000.pth")
  File "train_single_dqn.py", line 283, in test
    agent.q_network.load_state_dict(torch.load(load_path))
  File "/Users/user/anaconda3/envs/robot/lib/python3.8/site-packages/torch/serialization.py", line 1025, in load
    return _load(opened_zipfile,
  File "/Users/user/anaconda3/envs/robot/lib/python3.8/site-packages/torch/serialization.py", line 1446, in _load
    result = unpickler.load()
  File "/Users/user/anaconda3/envs/robot/lib/python3.8/site-packages/torch/serialization.py", line 1416, in persistent_load
    typed_storage = load_tensor(dtype, nbytes, key, _maybe_decode_ascii(location))
  File "/Users/user/anaconda3/envs/robot/lib/python3.8/site-packages/torch/serialization.py", line 1390, in load_tensor
    wrap_storage=restore_location(storage, location),
  File "/Users/user/anaconda3/envs/robot/lib/python3.8/site-packages/torch/serialization.py", line 390, in default_restore_location
    result = fn(storage, location)
  File "/Users/user/anaconda3/envs/robot/lib/python3.8/site-packages/torch/serialization.py", line 265, in _cuda_deserialize
    device = validate_cuda_device(location)
  File "/Users/user/anaconda3/envs/robot/lib/python3.8/site-packages/torch/serialization.py", line 249, in validate_cuda_device
    raise RuntimeError('Attempting to deserialize object on a CUDA '
RuntimeError: Attempting to deserialize object on a CUDA device but torch.cuda.is_available() is False. If you are running on a CPU-only machine, please use torch.load with map_location=torch.device('cpu') to map your storages to the CPU.
